Workbook

Sheet Data2026
A1: Affiliate Name | B1: Date | C1: Deal Type | D1: Affiliate Name | E1: Partner | F1: Payment Date | G1: Cost | H1: Status | I1: Source | J1: Starting date | K1: End Date | L1: Comments
A2: webopedia1 | B2: 46143 | C2: Listing | D2: webopedia1 | E2: Giorgi_Ts | H2: ongoing | I2: SEO | J2: 46143 | K2: 46234
A3: vetzx11 | B3: 46143 | C3: Fixed | D3: vetzx11 | E3: Giorgi_Ts | H3: ongoing | I3: SEO | J3: 46143 | K3: 46234
A4: top100book | B4: 46143 | C4: Listing | D4: top100book | E4: Giorgi_Ts | H4: ongoing | I4: SEO | J4: 46143 | K4: 46234
A5: cryptoCCN1 | B5: 46143 | C5: Listing | D5: cryptoCCN1 | E5: Giorgi_Ts | H5: Ongoing | I5: SEO | J5: 46143 | K5: 46234
A6: Atommal | B6: 46143 | C6: Listing | D6: Atommal | E6: Giorgi_Ts | H6: Ongoing | I6: SEO | J6: 46143 | K6: 46234
A7: Atanasos86 | B7: 46143 | C7: Listing | D7: Atanasos86 | E7: Giorgi_Ts | H7: Ongoing | I7: SEO | J7: 46143 | K7: 46234 | L7: Boosted
A8: BestCryptoCasino | B8: 46038 | C8: Listing | D8: BestCryptoCasino | E8: Elene_Gh | F8: 46038 | G8: 600 | H8: =IF(TODAY()>K8,"Finished",IF(TODAY()<J8,"Not Started","Ongoing")) -> Finished | I8: SEO | J8: 46038 | K8: 46068
A9: SBGC | B9: 46053 | C9: Listing | D9: SBGC | E9: Ani_S | F9: 46053 | G9: 5870 | H9: =IF(TODAY()>K9,"Finished",IF(TODAY()<J9,"Not Started","Ongoing")) -> Finished | I9: SEO | J9: 46023 | K9: 46053
A10: Coincodex | B10: 46053 | C10: Listing | D10: Coincodex | E10: Nugi | F10: 46053 | G10: 4193 | H10: =IF(TODAY()>K10,"Finished",IF(TODAY()<J10,"Not Started","Ongoing")) -> Finished | I10: SEO | J10: 46053 | K10: 46083 | L10: ეს ჩემი გადახდილი არ არის და არ ვიცი დაწყების და დამტავრების დღეები (Nigu, Iva)
A11: toprangemain | B11: 46077 | C11: Fixed | D11: toprangemain | E11: Nugi | F11: 46077 | G11: 2500 | H11: =IF(TODAY()>K11,"Finished",IF(TODAY()<J11,"Not Started","Ongoing")) -> Finished | I11: Meta | J11: 46077 | K11: 46107 | L11: არც ესაა ჩემი გადახდილი (Nugi)
A12: toprangemain | B12: 46077 | C12: Fixed | D12: toprangemain | E12: Nini_B | F12: 46077 | G12: 2500 | H12: =IF(TODAY()>K12,"Finished",IF(TODAY()<J12,"Not Started","Ongoing")) -> Finished | I12: Meta | J12: 46077 | K12: 46107
A13: profithunters | B13: 46077 | C13: Fixed | D13: profithunters | E13: Nugi | F13: 46077 | G13: 5518.58 | H13: =IF(TODAY()>K13,"Finished",IF(TODAY()<J13,"Not Started","Ongoing")) -> Finished | I13: Meta | J13: 46077 | K13: 46107 | L13: არაა ჩემი გადახდილი (Nugi)
A14: Firelink | B14: 46077 | C14: Fixed | D14: Firelink | E14: Nugi | F14: 46077 | G14: 889.98 | H14: =IF(TODAY()>K14,"Finished",IF(TODAY()<J14,"Not Started","Ongoing")) -> Finished | I14: SEO | J14: 46077 | K14: 46107
A15: Firelink | B15: 46077 | C15: Fixed | D15: Firelink | E15: Nugi | F15: 46077 | G15: 889.98 | H15: =IF(TODAY()>K15,"Finished",IF(TODAY()<J15,"Not Started","Ongoing")) -> Finished | I15: SEO | J15: 46077 | K15: 46107
A16: SBGC | B16: 46081 | C16: Fixed | D16: SBGC | E16: Ani_S | F16: 46081 | G16: 30156.21 | H16: =IF(TODAY()>K16,"Finished",IF(TODAY()<J16,"Not Started","Ongoing")) -> Finished | I16: SEO | J16: 46082 | K16: 46203
A17: coincodex | B17: 46081 | C17: Fixed | D17: coincodex | E17: Nini_B | F17: 46081 | G17: 8586.6 | H17: =IF(TODAY()>K17,"Finished",IF(TODAY()<J17,"Not Started","Ongoing")) -> Finished | I17: SEO | J17: 46081 | K17: 46111
A18: rocketlink | B18: 46082 | C18: Fixed | D18: rocketlink | E18: Nugi | F18: 46082 | G18: 1500 | H18: =IF(TODAY()>K18,"Finished",IF(TODAY()<J18,"Not Started","Ongoing")) -> Finished | I18: SEO | J18: 46082 | K18: 46112
A19: bwisemedia | B19: 46085 | C19: Fixed | D19: bwisemedia | E19: Elene_Gh | F19: 46085 | G19: 3062.32 | H19: =IF(TODAY()>K19,"Finished",IF(TODAY()<J19,"Not Started","Ongoing")) -> Finished | I19: DSP | J19: 46085 | K19: 46115
A20: andriiparfenov1 | B20: 46091 | C20: CPA | D20: andriiparfenov1 | E20: Elene_Gh | F20: 46091 | G20: 400 | H20: =IF(TODAY()>K20,"Finished",IF(TODAY()<J20,"Not Started","Ongoing")) -> Finished | I20: SEO | J20: 46091 | K20: 46121
A21: DappCentre | B21: 46093 | C21: Fixed | D21: DappCentre | E21: Nini_B | F21: 46093 | G21: 1423.29 | H21: =IF(TODAY()>K21,"Finished",IF(TODAY()<J21,"Not Started","Ongoing")) -> Finished | I21: Influence | J21: 46093 | K21: 46213 | L21: end date შევცვალე (2 კამპანია მქონდა მთლიანობაში)
A22: Ricardoc24 | B22: 46094 | C22: Fixed | D22: Ricardoc24 | E22: Nini_B | F22: 46094 | H22: =IF(TODAY()>K22,"Finished",IF(TODAY()<J22,"Not Started","Ongoing")) -> Finished | I22: Influence | J22: 46094 | K22: 46124
A23: Valek | B23: 46094 | C23: Fixed | D23: Valek | E23: Nini_B | F23: 46094 | G23: 2700.59 | H23: =IF(TODAY()>K23,"Finished",IF(TODAY()<J23,"Not Started","Ongoing")) -> Finished | I23: Influence | J23: 46094 | K23: 46124
A24: trimics2 | B24: 46094 | C24: Fixed | D24: trimics2 | E24: Nini_B | F24: 46094 | G24: 3479.61 | H24: =IF(TODAY()>K24,"Finished",IF(TODAY()<J24,"Not Started","Ongoing")) -> Finished | I24: Influence | J24: 46094 | K24: 46124
A25: bboladin26 | B25: 46094 | C25: Fixed | D25: bboladin26 | E25: Nini_B | F25: 46094 | H25: =IF(TODAY()>K25,"Finished",IF(TODAY()<J25,"Not Started","Ongoing")) -> Finished | I25: Influence | J25: 46094 | K25: 46124
A26: Mavaads | B26: 46098 | C26: Fixed | D26: Mavaads | E26: Nugi | F26: 46098 | G26: 11000 | H26: =IF(TODAY()>K26,"Finished",IF(TODAY()<J26,"Not Started","Ongoing")) -> Finished | I26: PPC | J26: 46098 | K26: 46128
A27: migzparcerias | B27: 46099 | C27: Fixed | D27: migzparcerias | E27: Nini_B | F27: 27/06/2026 | G27: 30850 | H27: =IF(TODAY()>K27,"Finished",IF(TODAY()<J27,"Not Started","Ongoing")) -> Finished | I27: Influence | J27: 46099 | K27: 46209 | L27: end date შევცვალე
A28: MrBooster | B28: 46100 | C28: Fixed | D28: MrBooster | E28: Nini_B | F28: 46100 | G28: 1663.78 | H28: =IF(TODAY()>K28,"Finished",IF(TODAY()<J28,"Not Started","Ongoing")) -> Finished | I28: Influence | J28: 46100 | K28: 46130
A29: SharkLink | B29: 46105 | C29: CPA | D29: SharkLink | E29: Nini_B | F29: 46105 | G29: 14492.91 | H29: =IF(TODAY()>K29,"Finished",IF(TODAY()<J29,"Not Started","Ongoing")) -> Finished | I29: Meta | J29: 46097 | K29: 46129
A30: moneturn | B30: 46106 | C30: Fixed | D30: moneturn | E30: Elene_Gh | F30: 46106 | G30: 1000 | H30: =IF(TODAY()>K30,"Finished",IF(TODAY()<J30,"Not Started","Ongoing")) -> Finished | I30: SEO | J30: 46097 | K30: 46129
A31: MightyCasino | B31: 46108 | C31: Fixed | D31: MightyCasino | E31: Nini_B | F31: 46108 | G31: 300 | H31: =IF(TODAY()>K31,"Finished",IF(TODAY()<J31,"Not Started","Ongoing")) -> Finished | I31: SEO | J31: 46097 | K31: 46129
A32: VALECHOBERK | B32: 46119 | C32: Fixed | D32: VALECHOBERK | E32: Nini_B | F32: 46119 | G32: 900 | H32: =IF(TODAY()>K32,"Finished",IF(TODAY()<J32,"Not Started","Ongoing")) -> Finished | I32: Influence | J32: 46130 | K32: 46145
A33: Rayconeta | B33: 46120 | C33: Fixed | D33: Rayconeta | E33: Elene_Gh | F33: 46120 | G33: 2708.04 | H33: =IF(TODAY()>K33,"Finished",IF(TODAY()<J33,"Not Started","Ongoing")) -> Finished | I33: Influence | J33: 46121 | K33: 46141
A34: seobroCA | B34: 46120 | C34: Fixed | D34: seobroCA | E34: Nini_B | F34: 46120 | G34: 2000 | H34: =IF(TODAY()>K34,"Finished",IF(TODAY()<J34,"Not Started","Ongoing")) -> Finished | I34: SEO | J34: 46143 | K34: 46173
A35: seobroCA | B35: 46120 | C35: Fixed | D35: seobroCA | E35: Nini_B | F35: 46120 | G35: 2000 | H35: =IF(TODAY()>K35,"Finished",IF(TODAY()<J35,"Not Started","Ongoing")) -> Finished | I35: SEO | J35: 46143 | K35: 46173
A36: ZnakiNL | B36: 46122 | C36: Fixed | D36: ZnakiNL | E36: Elene_Gh | F36: 46122 | G36: 800 | H36: =IF(TODAY()>K36,"Finished",IF(TODAY()<J36,"Not Started","Ongoing")) -> Finished | I36: SEO | J36: 46128 | K36: 46142
A37: totisuedd | B37: 46128 | C37: Fixed | D37: totisuedd | E37: Elene_Gh | F37: 46128 | G37: 679.93 | H37: =IF(TODAY()>K37,"Finished",IF(TODAY()<J37,"Not Started","Ongoing")) -> Finished | I37: Influence | J37: 46129 | K37: 46140
A38: Zukwaan | B38: 46129 | C38: Fixed | D38: Zukwaan | E38: Elene_Gh | F38: 46129 | G38: 382.1 | H38: =IF(TODAY()>K38,"Finished",IF(TODAY()<J38,"Not Started","Ongoing")) -> Finished | I38: Influence | J38: 46131 | K38: 46131
A39: vkngaffiliates | B39: 46135 | C39: Fixed | D39: vkngaffiliates | E39: Nini_B | F39: 46135 | G39: 372.34 | H39: =IF(TODAY()>K39,"Finished",IF(TODAY()<J39,"Not Started","Ongoing")) -> Finished | I39: Influence | J39: 46139 | K39: 46145
... A45: SAIDIteam | B45: 46139 | C45: Fixed | D45: SAIDIteam | E45: Nini_B | F45: 46139 | G45: 5000.86 | H45: =IF(TODAY()>K45,"Finished",IF(TODAY()<J45,"Not Started","Ongoing")) -> Finished | I45: Influence | J45: 46157 | K45: 46174
...

Sheet Data2025
A2: 2025 | B2: Jan | C2: Feb | D2: Mar | E2: Apr | F2: May | G2: Jun | H2: Jul | I2: Aug | J2: Sep | K2: Oct | L2: Nov | M2: Dec | N2: Total
A3: SEO | K3: 8666.67 | L3: 47333.33 | M3: 20000 | N3: =P3+ sum(I3:M3) -> 76000
A4: Brand | B4: 662.01 | C4: 662.01 | D4: 1462.01 | E4: 1571.9 | F4: 4826.05 | G4: 13961.43 | H4: 21756.18 | I4: 23158.7 | J4: 29075.59 | K4: 142.21 | L4: 23423.07 | M4: 6661.52 | N4: =P4+ sum(I4:M4) -> 82461.09
A5: Media | B5: 19089.66 | C5: 26961.96 | D5: 20308.64 | E5: 18387.42 | F5: 30858.3 | G5: 4323.36 | H5: 14177.86 | I5: 8786.1 | J5: 12814.72 | K5: 27916.79 | L5: 63228.51 | M5: 30271.27 | N5: =P5+ sum(I5:M5) -> 143017.39
A6: Community | F6: 881.36 | G6: 992.5 | H6: 128.86 | I6: 1664.13 | K6: 4064.13 | L6: 4604.9 | M6: 4719.41 | N6: =P6+ sum(I6:M6) -> 15052.57
A7: Influence | E7: 5775.51 | F7: 12262.65 | G7: 8082.12 | H7: 6664.04 | J7: 2657.15 | K7: 13146.7 | L7: 54437.32 | M7: 30524.26 | N7: =P7+ sum(I7:M7) -> 100765.43
A8: Affiliate SEO | B8: 34083.39 | C8: 34351.25 | D8: 44218.94 | E8: 33338.14 | F8: 12851.83 | G8: 17636.73 | H8: 13487.06 | I8: 13493.34 | J8: 16878.07 | K8: 48507.47 | L8: 27551.01 | M8: 30457.68 | N8: =P8+ sum(I8:M8) -> 136887.57
A9: Affiliate Meta | N9: =P9+ sum(I9:M9) -> 0
A10: Affiliate Tipster | N10: =P10+ sum(I10:M10) -> 0
A11: Affiliate PPC | N11: =P11+ sum(I11:M11) -> 0
A12: Affiliate DSP | N12: =P12+ sum(I12:M12) -> 0
A13: Other | F13: 8924 | G13: 8633 | H13: 28630 | I13: 42856 | K13: 28087 | N13: =P13+ sum(I13:M13) -> 70943
A14: Total | B14: =sum(B3:B13) -> 53835.06 | C14: =sum(C3:C13) -> 61975.22 | D14: =sum(D3:D13) -> 65989.59 | E14: =sum(E3:E13) -> 59072.97 | F14: =sum(F3:F13) -> 70604.19 | G14: =sum(G3:G13) -> 53629.14 | H14: =sum(H3:H13) -> 84844 | I14: =sum(I3:I13) -> 89958.27 | ... M14: =sum(M3:M13) -> 122634.14 | N14: =P14+ sum(I14:M14) -> 625127.05

Sheet Data Accrued
A1: Affiliate Name | B1: Date | C1: Deal Type | D1: Affiliate Name | E1: Partner | F1: Payment Date | G1: Cost | H1: Status | I1: Source | J1: Starting date | K1: End Date | L1: January accrued costs | M1: February accrued costs | N1: March accrued costs | O1: April accrued costs | P1: May accrued costs | Q1: June accrued costs | R1: January FTD | S1: February FTD | T1: March FTD | U1: April FTD | V1: May FTD | W1: June FTD | X1: January NGR | Y1: February NGR | Z1: March NGR | AA1: April NGR | AB1: May NGR | AC1: June NGR
A2: =Data2026!A8 -> BestCryptoCasino | B2: =Data2026!B8 -> 46038 | C2: =Data2026!C8 -> Listing | D2: =Data2026!D8 -> BestCryptoCasino | E2: =Data2026!E8 -> Elene_Gh | F2: =Data2026!F8 -> 46038 | G2: =Data2026!G8 -> 600 | H2: =Data2026!H8 -> Finished | ... K2: =Data2026!K8 -> 46068 | L2: =IF(OR($J2="",$K2="",$G2=""),0,IF($K2<=$J2,IF(AND($J2>=DATE(2026,1,1),$J2<EDATE(DATE(2026,1,1),1),TODAY()>=$J2),$G2,0),MAX(0,MIN(IF(TODAY()>$K2,$K2,TODAY()),EDATE(DATE(2026,1,1),1))-MAX($J2,DATE(2026,1,1)))*$G2/($K2-$J2))) -> 320 | M2: =IF(OR($J2="",$K2="",$G2=""),0,IF($K2<=$J2,IF(AND($J2>=DATE(2026,2,1),$J2<EDATE(DATE(2026,2,1),1),TODAY()>=$J2),$G2,0),MAX(0,MIN(IF(TODAY()>$K2,$K2,TODAY()),EDATE(DATE(2026,2,1),1))-MAX($J2,DATE(2026,2,1)))*$G2/($K2-$J2))) -> 280 | N2: =IF(OR($J2="",$K2="",$G2=""),0,IF($K2<=$J2,IF(AND($J2>=DATE(2026,3,1),$J2<EDATE(DATE(2026,3,1),1),TODAY()>=$J2),$G2,0),MAX(0,MIN(IF(TODAY()>$K2,$K2,TODAY()),EDATE(DATE(2026,3,1),1))-MAX($J2,DATE(2026,3,1)))*$G2/($K2-$J2))) -> 0 | O2: =IF(OR($J2="",$K2="",$G2=""),0,IF($K2<=$J2,IF(AND($J2>=DATE(2026,4,1),$J2<EDATE(DATE(2026,4,1),1),TODAY()>=$J2),$G2,0),MAX(0,MIN(IF(TODAY()>$K2,$K2,TODAY()),EDATE(DATE(2026,4,1),1))-MAX($J2,DATE(2026,4,1)))*$G2/($K2-$J2))) -> 0 | P2: =IF(OR($J2="",$K2="",$G2=""),0,IF($K2<=$J2,IF(AND($J2>=DATE(2026,5,1),$J2<EDATE(DATE(2026,5,1),1),TODAY()>=$J2),$G2,0),MAX(0,MIN(IF(TODAY()>$K2,$K2,TODAY()),EDATE(DATE(2026,5,1),1))-MAX($J2,DATE(2026,5,1)))*$G2/($K2-$J2))) -> 0 | Q2: =IF(OR($J2="",$K2="",$G2=""),0,IF($K2<=$J2,IF(AND($J2>=DATE(2026,6,1),$J2<EDATE(DATE(2026,5,1),1),TODAY()>=$J2),$G2,0),MAX(0,MIN(IF(TODAY()>$K2,$K2,TODAY()),EDATE(DATE(2026,6,1),1))-MAX($J2,DATE(2026,6,1)))*$G2/($K2-$J2))) -> 0 | R2: =SUMIF(Tableau!$A:$A,$A2,Tableau!E:E) -> #N/A | S2: =SUMIF(Tableau!$A:$A,$A2,Tableau!F:F) -> #N/A | T2: =SUMIF(Tableau!$A:$A,$A2,Tableau!G:G) -> #N/A | U2: =SUMIF(Tableau!$A:$A,$A2,Tableau!H:H) -> #N/A | V2: =SUMIF(Tableau!$A:$A,$A2,Tableau!I:I) -> #N/A | W2: =SUMIF(Tableau!$A:$A,$A2,Tableau!J:J) -> #N/A | AL2: Total | AV2: Total
A3: =Data2026!A9 -> SBGC | B3: =Data2026!B9 -> 46053 | C3: =Data2026!C9 -> Listing | D3: =Data2026!D9 -> SBGC | E3: =Data2026!E9 -> Ani_S | F3: =Data2026!F9 -> 46053 | G3: =Data2026!G9 -> 5870 | H3: =Data2026!H9 -> Finished | ... K3: =Data2026!K9 -> 46053 | L3: =IF(OR($J3="",$K3="",$G3=""),0,IF($K3<=$J3,IF(AND($J3>=DATE(2026,1,1),$J3<EDATE(DATE(2026,1,1),1),TODAY()>=$J3),$G3,0),MAX(0,MIN(IF(TODAY()>$K3,$K3,TODAY()),EDATE(DATE(2026,1,1),1))-MAX($J3,DATE(2026,1,1)))*$G3/($K3-$J3))) -> 5870 | M3: =IF(OR($J3="",$K3="",$G3=""),0,IF($K3<=$J3,IF(AND($J3>=DATE(2026,2,1),$J3<EDATE(DATE(2026,2,1),1),TODAY()>=$J3),$G3,0),MAX(0,MIN(IF(TODAY()>$K3,$K3,TODAY()),EDATE(DATE(2026,2,1),1))-MAX($J3,DATE(2026,2,1)))*$G3/($K3-$J3))) -> 0 | N3: =IF(OR($J3="",$K3="",$G3=""),0,IF($K3<=$J3,IF(AND($J3>=DATE(2026,3,1),$J3<EDATE(DATE(2026,3,1),1),TODAY()>=$J3),$G3,0),MAX(0,MIN(IF(TODAY()>$K3,$K3,TODAY()),EDATE(DATE(2026,3,1),1))-MAX($J3,DATE(2026,3,1)))*$G3/($K3-$J3))) -> 0 | O3: =IF(OR($J3="",$K3="",$G3=""),0,IF($K3<=$J3,IF(AND($J3>=DATE(2026,4,1),$J3<EDATE(DATE(2026,4,1),1),TODAY()>=$J3),$G3,0),MAX(0,MIN(IF(TODAY()>$K3,$K3,TODAY()),EDATE(DATE(2026,4,1),1))-MAX($J3,DATE(2026,4,1)))*$G3/($K3-$J3))) -> 0 | P3: =IF(OR($J3="",$K3="",$G3=""),0,IF($K3<=$J3,IF(AND($J3>=DATE(2026,5,1),$J3<EDATE(DATE(2026,5,1),1),TODAY()>=$J3),$G3,0),MAX(0,MIN(IF(TODAY()>$K3,$K3,TODAY()),EDATE(DATE(2026,5,1),1))-MAX($J3,DATE(2026,5,1)))*$G3/($K3-$J3))) -> 0 | Q3: =IF(OR($J3="",$K3="",$G3=""),0,IF($K3<=$J3,IF(AND($J3>=DATE(2026,6,1),$J3<EDATE(DATE(2026,5,1),1),TODAY()>=$J3),$G3,0),MAX(0,MIN(IF(TODAY()>$K3,$K3,TODAY()),EDATE(DATE(2026,6,1),1))-MAX($J3,DATE(2026,6,1)))*$G3/($K3-$J3))) -> 0 | R3: =SUMIF(Tableau!$A:$A,$A3,Tableau!E:E) -> #N/A | S3: =SUMIF(Tableau!$A:$A,$A3,Tableau!F:F) -> #N/A | W3: =SUMIF(Tableau!$A:$A,$A3,Tableau!J:J) -> #N/A | X3: =SUMIF(Tableau!$A:$A,$A3,Tableau!P:P) -> #N/A | Y3: =SUMIF(Tableau!$A:$A,$A3,Tableau!Q:Q) -> #N/A | Z3: =SUMIF(Tableau!$A:$A,$A3,Tableau!R:R) -> #N/A | AA3: =SUMIF(Tableau!$A:$A,$A3,Tableau!S:S) -> #N/A | AB3: =SUMIF(Tableau!$A:$A,$A3,Tableau!T:T) -> #N/A | AC3: =SUMIF(Tableau!$A:$A,$A3,Tableau!U:U) -> #N/A | AL3: =SUM(AF3:AK3) -> #REF! | AV3: =SUM(AP3:AU3) -> #N/A
A4: =Data2026!A10 -> Coincodex | B4: =Data2026!B10 -> 46053 | C4: =Data2026!C10 -> Listing | D4: =Data2026!D10 -> Coincodex | E4: =Data2026!E10 -> Nugi | F4: =Data2026!F10 -> 46053 | G4: =Data2026!G10 -> 4193 | H4: =Data2026!H10 -> Finished | ... K4: =Data2026!K10 -> 46083 | L4: =IF(OR($J4="",$K4="",$G4=""),0,IF($K4<=$J4,IF(AND($J4>=DATE(2026,1,1),$J4<EDATE(DATE(2026,1,1),1),TODAY()>=$J4),$G4,0),MAX(0,MIN(IF(TODAY()>$K4,$K4,TODAY()),EDATE(DATE(2026,1,1),1))-MAX($J4,DATE(2026,1,1)))*$G4/($K4-$J4))) -> 139.76667 | M4: =IF(OR($J4="",$K4="",$G4=""),0,IF($K4<=$J4,IF(AND($J4>=DATE(2026,2,1),$J4<EDATE(DATE(2026,2,1),1),TODAY()>=$J4),$G4,0),MAX(0,MIN(IF(TODAY()>$K4,$K4,TODAY()),EDATE(DATE(2026,2,1),1))-MAX($J4,DATE(2026,2,1)))*$G4/($K4-$J4))) -> 3913.4667 | N4: =IF(OR($J4="",$K4="",$G4=""),0,IF($K4<=$J4,IF(AND($J4>=DATE(2026,3,1),$J4<EDATE(DATE(2026,3,1),1),TODAY()>=$J4),$G4,0),MAX(0,MIN(IF(TODAY()>$K4,$K4,TODAY()),EDATE(DATE(2026,3,1),1))-MAX($J4,DATE(2026,3,1)))*$G4/($K4-$J4))) -> 139.76667 | O4: =IF(OR($J4="",$K4="",$G4=""),0,IF($K4<=$J4,IF(AND($J4>=DATE(2026,4,1),$J4<EDATE(DATE(2026,4,1),1),TODAY()>=$J4),$G4,0),MAX(0,MIN(IF(TODAY()>$K4,$K4,TODAY()),EDATE(DATE(2026,4,1),1))-MAX($J4,DATE(2026,4,1)))*$G4/($K4-$J4))) -> 0 | P4: =IF(OR($J4="",$K4="",$G4=""),0,IF($K4<=$J4,IF(AND($J4>=DATE(2026,5,1),$J4<EDATE(DATE(2026,5,1),1),TODAY()>=$J4),$G4,0),MAX(0,MIN(IF(TODAY()>$K4,$K4,TODAY()),EDATE(DATE(2026,5,1),1))-MAX($J4,DATE(2026,5,1)))*$G4/($K4-$J4))) -> 0 | Q4: =IF(OR($J4="",$K4="",$G4=""),0,IF($K4<=$J4,IF(AND($J4>=DATE(2026,6,1),$J4<EDATE(DATE(2026,5,1),1),TODAY()>=$J4),$G4,0),MAX(0,MIN(IF(TODAY()>$K4,$K4,TODAY()),EDATE(DATE(2026,6,1),1))-MAX($J4,DATE(2026,6,1)))*$G4/($K4-$J4))) -> 0 | R4: =SUMIF(Tableau!$A:$A,$A4,Tableau!E:E) -> #N/A | S4: =SUMIF(Tableau!$A:$A,$A4,Tableau!F:F) -> #N/A | T4: =SUMIF(Tableau!$A:$A,$A4,Tableau!G:G) -> #N/A | U4: =SUMIF(Tableau!$A:$A,$A4,Tableau!H:H) -> #N/A | V4: =SUMIF(Tableau!$A:$A,$A4,Tableau!I:I) -> #N/A | W4: =SUMIF(Tableau!$A:$A,$A4,Tableau!J:J) -> #N/A | X4: =SUMIF(Tableau!$A:$A,$A4,Tableau!P:P) -> #N/A | Y4: =SUMIF(Tableau!$A:$A,$A4,Tableau!Q:Q) -> #N/A | Z4: =SUMIF(Tableau!$A:$A,$A4,Tableau!R:R) -> #N/A | AA4: =SUMIF(Tableau!$A:$A,$A4,Tableau!S:S) -> #N/A | AB4: =SUMIF(Tableau!$A:$A,$A4,Tableau!T:T) -> #N/A | AC4: =SUMIF(Tableau!$A:$A,$A4,Tableau!U:U) -> #N/A | AL4: Total | AV4: =SUM(AP4:AU4) -> #N/A
A5: =Data2026!A11 -> toprangemain | B5: =Data2026!B11 -> 46077 | C5: =Data2026!C11 -> Fixed | D5: =Data2026!D11 -> toprangemain | E5: =Data2026!E11 -> Nugi | F5: =Data2026!F11 -> 46077 | G5: =Data2026!G11 -> 2500 | H5: =Data2026!H11 -> Finished | ... K5: =Data2026!K11 -> 46107 | L5: =IF(OR($J5="",$K5="",$G5=""),0,IF($K5<=$J5,IF(AND($J5>=DATE(2026,1,1),$J5<EDATE(DATE(2026,1,1),1),TODAY()>=$J5),$G5,0),MAX(0,MIN(IF(TODAY()>$K5,$K5,TODAY()),EDATE(DATE(2026,1,1),1))-MAX($J5,DATE(2026,1,1)))*$G5/($K5-$J5))) -> 0 | M5: =IF(OR($J5="",$K5="",$G5=""),0,IF($K5<=$J5,IF(AND($J5>=DATE(2026,2,1),$J5<EDATE(DATE(2026,2,1),1),TODAY()>=$J5),$G5,0),MAX(0,MIN(IF(TODAY()>$K5,$K5,TODAY()),EDATE(DATE(2026,2,1),1))-MAX($J5,DATE(2026,2,1)))*$G5/($K5-$J5))) -> 416.66667 | N5: =IF(OR($J5="",$K5="",$G5=""),0,IF($K5<=$J5,IF(AND($J5>=DATE(2026,3,1),$J5<EDATE(DATE(2026,3,1),1),TODAY()>=$J5),$G5,0),MAX(0,MIN(IF(TODAY()>$K5,$K5,TODAY()),EDATE(DATE(2026,3,1),1))-MAX($J5,DATE(2026,3,1)))*$G5/($K5-$J5))) -> 2083.3333 | O5: =IF(OR($J5="",$K5="",$G5=""),0,IF($K5<=$J5,IF(AND($J5>=DATE(2026,4,1),$J5<EDATE(DATE(2026,4,1),1),TODAY()>=$J5),$G5,0),MAX(0,MIN(IF(TODAY()>$K5,$K5,TODAY()),EDATE(DATE(2026,4,1),1))-MAX($J5,DATE(2026,4,1)))*$G5/($K5-$J5))) -> 0 | P5: =IF(OR($J5="",$K5="",$G5=""),0,IF($K5<=$J5,IF(AND($J5>=DATE(2026,5,1),$J5<EDATE(DATE(2026,5,1),1),TODAY()>=$J5),$G5,0),MAX(0,MIN(IF(TODAY()>$K5,$K5,TODAY()),EDATE(DATE(2026,5,1),1))-MAX($J5,DATE(2026,5,1)))*$G5/($K5-$J5))) -> 0 | Q5: =IF(OR($J5="",$K5="",$G5=""),0,IF($K5<=$J5,IF(AND($J5>=DATE(2026,6,1),$J5<EDATE(DATE(2026,5,1),1),TODAY()>=$J5),$G5,0),MAX(0,MIN(IF(TODAY()>$K5,$K5,TODAY()),EDATE(DATE(2026,6,1),1))-MAX($J5,DATE(2026,6,1)))*$G5/($K5-$J5))) -> 0 | R5: =SUMIF(Tableau!$A:$A,$A5,Tableau!E:E) -> #N/A | S5: =SUMIF(Tableau!$A:$A,$A5,Tableau!F:F) -> #N/A | T5: =SUMIF(Tableau!$A:$A,$A5,Tableau!G:G) -> #N/A | U5: =SUMIF(Tableau!$A:$A,$A5,Tableau!H:H) -> #N/A | V5: =SUMIF(Tableau!$A:$A,$A5,Tableau!I:I) -> #N/A | W5: =SUMIF(Tableau!$A:$A,$A5,Tableau!J:J) -> #N/A | X5: =SUMIF(Tableau!$A:$A,$A5,Tableau!P:P) -> #N/A | Y5: =SUMIF(Tableau!$A:$A,$A5,Tableau!Q:Q) -> #N/A | Z5: =SUMIF(Tableau!$A:$A,$A5,Tableau!R:R) -> #N/A | AA5: =SUMIF(Tableau!$A:$A,$A5,Tableau!S:S) -> #N/A | AB5: =SUMIF(Tableau!$A:$A,$A5,Tableau!T:T) -> #N/A | AC5: =SUMIF(Tableau!$A:$A,$A5,Tableau!U:U) -> #N/A | AL5: =SUM(AF5:AK5) -> #N/A | AV5: =SUM(AP5:AU5) -> #N/A | CF5: JAN CPA | CG5: FEB CPA | CH5: MAR CPA | CI5: APR CPA | CJ5: MAY CPA | CK5: JUN CPA
A6: =Data2026!A12 -> toprangemain | B6: =Data2026!B12 -> 46077 | C6: =Data2026!C12 -> Fixed | D6: =Data2026!D12 -> toprangemain | E6: =Data2026!E12 -> Nini_B | F6: =Data2026!F12 -> 46077 | G6: =Data2026!G12 -> 2500 | H6: =Data2026!H12 -> Finished | ... K6: =Data2026!K12 -> 46107 | L6: =IF(OR($J6="",$K6="",$G6=""),0,IF($K6<=$J6,IF(AND($J6>=DATE(2026,1,1),$J6<EDATE(DATE(2026,1,1),1),TODAY()>=$J6),$G6,0),MAX(0,MIN(IF(TODAY()>$K6,$K6,TODAY()),EDATE(DATE(2026,1,1),1))-MAX($J6,DATE(2026,1,1)))*$G6/($K6-$J6))) -> 0 | M6: =IF(OR($J6="",$K6="",$G6=""),0,IF($K6<=$J6,IF(AND($J6>=DATE(2026,2,1),$J6<EDATE(DATE(2026,2,1),1),TODAY()>=$J6),$G6,0),MAX(0,MIN(IF(TODAY()>$K6,$K6,TODAY()),EDATE(DATE(2026,2,1),1))-MAX($J6,DATE(2026,2,1)))*$G6/($K6-$J6))) -> 416.66667 | N6: =IF(OR($J6="",$K6="",$G6=""),0,IF($K6<=$J6,IF(AND($J6>=DATE(2026,3,1),$J6<EDATE(DATE(2026,3,1),1),TODAY()>=$J6),$G6,0),MAX(0,MIN(IF(TODAY()>$K6,$K6,TODAY()),EDATE(DATE(2026,3,1),1))-MAX($J6,DATE(2026,3,1)))*$G6/($K6-$J6))) -> 2083.3333 | O6: =IF(OR($J6="",$K6="",$G6=""),0,IF($K6<=$J6,IF(AND($J6>=DATE(2026,4,1),$J6<EDATE(DATE(2026,4,1),1),TODAY()>=$J6),$G6,0),MAX(0,MIN(IF(TODAY()>$K6,$K6,TODAY()),EDATE(DATE(2026,4,1),1))-MAX($J6,DATE(2026,4,1)))*$G6/($K6-$J6))) -> 0 | P6: =IF(OR($J6="",$K6="",$G6=""),0,IF($K6<=$J6,IF(AND($J6>=DATE(2026,5,1),$J6<EDATE(DATE(2026,5,1),1),TODAY()>=$J6),$G6,0),MAX(0,MIN(IF(TODAY()>$K6,$K6,TODAY()),EDATE(DATE(2026,5,1),1))-MAX($J6,DATE(2026,5,1)))*$G6/($K6-$J6))) -> 0 | Q6: =IF(OR($J6="",$K6="",$G6=""),0,IF($K6<=$J6,IF(AND($J6>=DATE(2026,6,1),$J6<EDATE(DATE(2026,5,1),1),TODAY()>=$J6),$G6,0),MAX(0,MIN(IF(TODAY()>$K6,$K6,TODAY()),EDATE(DATE(2026,6,1),1))-MAX($J6,DATE(2026,6,1)))*$G6/($K6-$J6))) -> 0 | W6: =SUMIF(Tableau!$A:$A,$A6,Tableau!J:J) -> #N/A | X6: =SUMIF(Tableau!$A:$A,$A6,Tableau!P:P) -> #N/A | Y6: =SUMIF(Tableau!$A:$A,$A6,Tableau!Q:Q) -> #N/A | Z6: =SUMIF(Tableau!$A:$A,$A6,Tableau!R:R) -> #N/A | AA6: =SUMIF(Tableau!$A:$A,$A6,Tableau!S:S) -> #N/A | AB6: =SUMIF(Tableau!$A:$A,$A6,Tableau!T:T) -> #N/A | AC6: =SUMIF(Tableau!$A:$A,$A6,Tableau!U:U) -> #N/A | AF6: Jan CPA | AG6: Feb CPA | AH6: Mar CPA | AI6: April CPA | AJ6: May CPA | AK6: June CPA | AL6: Total | AV6: =SUM(AP6:AU6) -> #N/A | CF6: =IFERROR(BT6/BZ6,0) -> 0 | CG6: =IFERROR(BU6/CA6,0) -> 0 | CH6: =IFERROR(BV6/CB6,0) -> 0 | CI6: =IFERROR(BW6/CC6,0) -> 0 | CJ6: =IFERROR(BX6/CD6,0) -> 0 | CK6: =IFERROR(BY6/CE6,0) -> 0
A7: =Data2026!A13 -> profithunters | B7: =Data2026!B13 -> 46077 | C7: =Data2026!C13 -> Fixed | D7: =Data2026!D13 -> profithunters | E7: =Data2026!E13 -> Nugi | F7: =Data2026!F13 -> 46077 | G7: =Data2026!G13 -> 5518.58 | H7: =Data2026!H13 -> Finished | ... K7: =Data2026!K13 -> 46107 | L7: =IF(OR($J7="",$K7="",$G7=""),0,IF($K7<=$J7,IF(AND($J7>=DATE(2026,1,1),$J7<EDATE(DATE(2026,1,1),1),TODAY()>=$J7),$G7,0),MAX(0,MIN(IF(TODAY()>$K7,$K7,TODAY()),EDATE(DATE(2026,1,1),1))-MAX($J7,DATE(2026,1,1)))*$G7/($K7-$J7))) -> 0 | M7: =IF(OR($J7="",$K7="",$G7=""),0,IF($K7<=$J7,IF(AND($J7>=DATE(2026,2,1),$J7<EDATE(DATE(2026,2,1),1),TODAY()>=$J7),$G7,0),MAX(0,MIN(IF(TODAY()>$K7,$K7,TODAY()),EDATE(DATE(2026,2,1),1))-MAX($J7,DATE(2026,2,1)))*$G7/($K7-$J7))) -> 919.76333 | N7: =IF(OR($J7="",$K7="",$G7=""),0,IF($K7<=$J7,IF(AND($J7>=DATE(2026,3,1),$J7<EDATE(DATE(2026,3,1),1),TODAY()>=$J7),$G7,0),MAX(0,MIN(IF(TODAY()>$K7,$K7,TODAY()),EDATE(DATE(2026,3,1),1))-MAX($J7,DATE(2026,3,1)))*$G7/($K7-$J7))) -> 4598.8167 | O7: =IF(OR($J7="",$K7="",$G7=""),0,IF($K7<=$J7,IF(AND($J7>=DATE(2026,4,1),$J7<EDATE(DATE(2026,4,1),1),TODAY()>=$J7),$G7,0),MAX(0,MIN(IF(TODAY()>$K7,$K7,TODAY()),EDATE(DATE(2026,4,1),1))-MAX($J7,DATE(2026,4,1)))*$G7/($K7-$J7))) -> 0 | P7: =IF(OR($J7="",$K7="",$G7=""),0,IF($K7<=$J7,IF(AND($J7>=DATE(2026,5,1),$J7<EDATE(DATE(2026,5,1),1),TODAY()>=$J7),$G7,0),MAX(0,MIN(IF(TODAY()>$K7,$K7,TODAY()),EDATE(DATE(2026,5,1),1))-MAX($J7,DATE(2026,5,1)))*$G7/($K7-$J7))) -> 0 | Q7: =IF(OR($J7="",$K7="",$G7=""),0,IF($K7<=$J7,IF(AND($J7>=DATE(2026,6,1),$J7<EDATE(DATE(2026,5,1),1),TODAY()>=$J7),$G7,0),MAX(0,MIN(IF(TODAY()>$K7,$K7,TODAY()),EDATE(DATE(2026,6,1),1))-MAX($J7,DATE(2026,6,1)))*$G7/($K7-$J7))) -> 0 | R7: =SUMIF(Tableau!$A:$A,$A7,Tableau!E:E) -> #N/A | S7: =SUMIF(Tableau!$A:$A,$A7,Tableau!F:F) -> #N/A | T7: =SUMIF(Tableau!$A:$A,$A7,Tableau!G:G) -> #N/A | U7: =SUMIF(Tableau!$A:$A,$A7,Tableau!H:H) -> #N/A | V7: =SUMIF(Tableau!$A:$A,$A7,Tableau!I:I) -> #N/A | W7: =SUMIF(Tableau!$A:$A,$A7,Tableau!J:J) -> #N/A | X7: =SUMIF(Tableau!$A:$A,$A7,Tableau!P:P) -> #N/A | Y7: =SUMIF(Tableau!$A:$A,$A7,Tableau!Q:Q) -> #N/A | Z7: =SUMIF(Tableau!$A:$A,$A7,Tableau!R:R) -> #N/A | AA7: =SUMIF(Tableau!$A:$A,$A7,Tableau!S:S) -> #N/A | AB7: =SUMIF(Tableau!$A:$A,$A7,Tableau!T:T) -> #N/A | AC7: =SUMIF(Tableau!$A:$A,$A7,Tableau!U:U) -> #N/A | AF7: =AF3/AF5 -> #REF! | AG7: =AG3/AG5 -> #REF! | AH7: =AH3/AH5 -> #REF! | AI7: =AI3/AI5 -> #REF! | AJ7: =AJ3/AJ5 -> #REF! | AK7: =AK3/AK5 -> #REF! | AL7: =AL3/AL5 -> #REF! | AV7: =SUM(AP7:AU7) -> #N/A | CF7: =IFERROR(BT7/BZ7,0) -> 0 | CG7: =IFERROR(BU7/CA7,0) -> 0 | CH7: =IFERROR(BV7/CB7,0) -> 0 | CI7: =IFERROR(BW7/CC7,0) -> 0 | CJ7: =IFERROR(BX7/CD7,0) -> 0 | CK7: =IFERROR(BY7/CE7,0) -> 0
A8: =Data2026!A14 -> Firelink | B8: =Data2026!B14 -> 46077 | C8: =Data2026!C14 -> Fixed | D8: =Data2026!D14 -> Firelink | E8: =Data2026!E14 -> Nugi | F8: =Data2026!F14 -> 46077 | G8: =Data2026!G14 -> 889.98 | H8: =Data2026!H14 -> Finished | ... K8: =Data2026!K14 -> 46107 | L8: =IF(OR($J8="",$K8="",$G8=""),0,IF($K8<=$J8,IF(AND($J8>=DATE(2026,1,1),$J8<EDATE(DATE(2026,1,1),1),TODAY()>=$J8),$G8,0),MAX(0,MIN(IF(TODAY()>$K8,$K8,TODAY()),EDATE(DATE(2026,1,1),1))-MAX($J8,DATE(2026,1,1)))*$G8/($K8-$J8))) -> 0 | M8: =IF(OR($J8="",$K8="",$G8=""),0,IF($K8<=$J8,IF(AND($J8>=DATE(2026,2,1),$J8<EDATE(DATE(2026,2,1),1),TODAY()>=$J8),$G8,0),MAX(0,MIN(IF(TODAY()>$K8,$K8,TODAY()),EDATE(DATE(2026,2,1),1))-MAX($J8,DATE(2026,2,1)))*$G8/($K8-$J8))) -> 148.33 | N8: =IF(OR($J8="",$K8="",$G8=""),0,IF($K8<=$J8,IF(AND($J8>=DATE(2026,3,1),$J8<EDATE(DATE(2026,3,1),1),TODAY()>=$J8),$G8,0),MAX(0,MIN(IF(TODAY()>$K8,$K8,TODAY()),EDATE(DATE(2026,3,1),1))-MAX($J8,DATE(2026,3,1)))*$G8/($K8-$J8))) -> 741.65 | O8: =IF(OR($J8="",$K8="",$G8=""),0,IF($K8<=$J8,IF(AND($J8>=DATE(2026,4,1),$J8<EDATE(DATE(2026,4,1),1),TODAY()>=$J8),$G8,0),MAX(0,MIN(IF(TODAY()>$K8,$K8,TODAY()),EDATE(DATE(2026,4,1),1))-MAX($J8,DATE(2026,4,1)))*$G8/($K8-$J8))) -> 0 | P8: =IF(OR($J8="",$K8="",$G8=""),0,IF($K8<=$J8,IF(AND($J8>=DATE(2026,5,1),$J8<EDATE(DATE(2026,5,1),1),TODAY()>=$J8),$G8,0),MAX(0,MIN(IF(TODAY()>$K8,$K8,TODAY()),EDATE(DATE(2026,5,1),1))-MAX($J8,DATE(2026,5,1)))*$G8/($K8-$J8))) -> 0 | Q8: =IF(OR($J8="",$K8="",$G8=""),0,IF($K8<=$J8,IF(AND($J8>=DATE(2026,6,1),$J8<EDATE(DATE(2026,5,1),1),TODAY()>=$J8),$G8,0),MAX(0,MIN(IF(TODAY()>$K8,$K8,TODAY()),EDATE(DATE(2026,6,1),1))-MAX($J8,DATE(2026,6,1)))*$G8/($K8-$J8))) -> 0 | R8: =SUMIF(Tableau!$A:$A,$A8,Tableau!E:E) -> #N/A | S8: =SUMIF(Tableau!$A:$A,$A8,Tableau!F:F) -> #N/A | T8: =SUMIF(Tableau!$A:$A,$A8,Tableau!G:G) -> #N/A | U8: =SUMIF(Tableau!$A:$A,$A8,Tableau!H:H) -> #N/A | V8: =SUMIF(Tableau!$A:$A,$A8,Tableau!I:I) -> #N/A | W8: =SUMIF(Tableau!$A:$A,$A8,Tableau!J:J) -> #N/A | X8: =SUMIF(Tableau!$A:$A,$A8,Tableau!P:P) -> #N/A | Y8: =SUMIF(Tableau!$A:$A,$A8,Tableau!Q:Q) -> #N/A | Z8: =SUMIF(Tableau!$A:$A,$A8,Tableau!R:R) -> #N/A | AA8: =SUMIF(Tableau!$A:$A,$A8,Tableau!S:S) -> #N/A | AB8: =SUMIF(Tableau!$A:$A,$A8,Tableau!T:T) -> #N/A | AC8: =SUMIF(Tableau!$A:$A,$A8,Tableau!U:U) -> #N/A | AV8: =SUM(AP8:AU8) -> #N/A | CF8: =IFERROR(BT8/BZ8,0) -> 0 | CG8: =IFERROR(BU8/CA8,0) -> 0 | CH8: =IFERROR(BV8/CB8,0) -> 0 | CI8: =IFERROR(BW8/CC8,0) -> 0 | CJ8: =IFERROR(BX8/CD8,0) -> 0 | CK8: =IFERROR(BY8/CE8,0) -> 0
A9: =Data2026!A15 -> Firelink | B9: =Data2026!B15 -> 46077 | C9: =Data2026!C15 -> Fixed | D9: =Data2026!D15 -> Firelink | E9: =Data2026!E15 -> Nugi | F9: =Data2026!F15 -> 46077 | G9: =Data2026!G15 -> 889.98 | H9: =Data2026!H15 -> Finished | ... K9: =Data2026!K15 -> 46107 | L9: =IF(OR($J9="",$K9="",$G9=""),0,IF($K9<=$J9,IF(AND($J9>=DATE(2026,1,1),$J9<EDATE(DATE(2026,1,1),1),TODAY()>=$J9),$G9,0),MAX(0,MIN(IF(TODAY()>$K9,$K9,TODAY()),EDATE(DATE(2026,1,1),1))-MAX($J9,DATE(2026,1,1)))*$G9/($K9-$J9))) -> 0 | M9: =IF(OR($J9="",$K9="",$G9=""),0,IF($K9<=$J9,IF(AND($J9>=DATE(2026,2,1),$J9<EDATE(DATE(2026,2,1),1),TODAY()>=$J9),$G9,0),MAX(0,MIN(IF(TODAY()>$K9,$K9,TODAY()),EDATE(DATE(2026,2,1),1))-MAX($J9,DATE(2026,2,1)))*$G9/($K9-$J9))) -> 148.33 | N9: =IF(OR($J9="",$K9="",$G9=""),0,IF($K9<=$J9,IF(AND($J9>=DATE(2026,3,1),$J9<EDATE(DATE(2026,3,1),1),TODAY()>=$J9),$G9,0),MAX(0,MIN(IF(TODAY()>$K9,$K9,TODAY()),EDATE(DATE(2026,3,1),1))-MAX($J9,DATE(2026,3,1)))*$G9/($K9-$J9))) -> 741.65 | O9: =IF(OR($J9="",$K9="",$G9=""),0,IF($K9<=$J9,IF(AND($J9>=DATE(2026,4,1),$J9<EDATE(DATE(2026,4,1),1),TODAY()>=$J9),$G9,0),MAX(0,MIN(IF(TODAY()>$K9,$K9,TODAY()),EDATE(DATE(2026,4,1),1))-MAX($J9,DATE(2026,4,1)))*$G9/($K9-$J9))) -> 0 | P9: =IF(OR($J9="",$K9="",$G9=""),0,IF($K9<=$J9,IF(AND($J9>=DATE(2026,5,1),$J9<EDATE(DATE(2026,5,1),1),TODAY()>=$J9),$G9,0),MAX(0,MIN(IF(TODAY()>$K9,$K9,TODAY()),EDATE(DATE(2026,5,1),1))-MAX($J9,DATE(2026,5,1)))*$G9/($K9-$J9))) -> 0 | Q9: =IF(OR($J9="",$K9="",$G9=""),0,IF($K9<=$J9,IF(AND($J9>=DATE(2026,6,1),$J9<EDATE(DATE(2026,5,1),1),TODAY()>=$J9),$G9,0),MAX(0,MIN(IF(TODAY()>$K9,$K9,TODAY()),EDATE(DATE(2026,6,1),1))-MAX($J9,DATE(2026,6,1)))*$G9/($K9-$J9))) -> 0 | R9: =SUMIF(Tableau!$A:$A,$A9,Tableau!E:E) -> #N/A | S9: =SUMIF(Tableau!$A:$A,$A9,Tableau!F:F) -> #N/A | W9: =SUMIF(Tableau!$A:$A,$A9,Tableau!J:J) -> #N/A | X9: =SUMIF(Tableau!$A:$A,$A9,Tableau!P:P) -> #N/A | Y9: =SUMIF(Tableau!$A:$A,$A9,Tableau!Q:Q) -> #N/A | Z9: =SUMIF(Tableau!$A:$A,$A9,Tableau!R:R) -> #N/A | AV9: =SUM(AP9:AU9) -> #N/A | CF9: =IFERROR(BT9/BZ9,0) -> 0 | CG9: =IFERROR(BU9/CA9,0) -> 0 | CH9: =IFERROR(BV9/CB9,0) -> 0 | CI9: =IFERROR(BW9/CC9,0) -> 0 | CJ9: =IFERROR(BX9/CD9,0) -> 0 | CK9: =IFERROR(BY9/CE9,0) -> 0
A10: =Data2026!A16 -> SBGC | B10: =Data2026!B16 -> 46081 | C10: =Data2026!C16 -> Fixed | D10: =Data2026!D16 -> SBGC | E10: =Data2026!E16 -> Ani_S | F10: =Data2026!F16 -> 46081 | G10: =Data2026!G16 -> 30156.21 | H10: =Data2026!H16 -> Finished | ... K10: =Data2026!K16 -> 46203 | L10: =IF(OR($J10="",$K10="",$G10=""),0,IF($K10<=$J10,IF(AND($J10>=DATE(2026,1,1),$J10<EDATE(DATE(2026,1,1),1),TODAY()>=$J10),$G10,0),MAX(0,MIN(IF(TODAY()>$K10,$K10,TODAY()),EDATE(DATE(2026,1,1),1))-MAX($J10,DATE(2026,1,1)))*$G10/($K10-$J10))) -> 0 | M10: =IF(OR($J10="",$K10="",$G10=""),0,IF($K10<=$J10,IF(AND($J10>=DATE(2026,2,1),$J10<EDATE(DATE(2026,2,1),1),TODAY()>=$J10),$G10,0),MAX(0,MIN(IF(TODAY()>$K10,$K10,TODAY()),EDATE(DATE(2026,2,1),1))-MAX($J10,DATE(2026,2,1)))*$G10/($K10-$J10))) -> 0 | N10: =IF(OR($J10="",$K10="",$G10=""),0,IF($K10<=$J10,IF(AND($J10>=DATE(2026,3,1),$J10<EDATE(DATE(2026,3,1),1),TODAY()>=$J10),$G10,0),MAX(0,MIN(IF(TODAY()>$K10,$K10,TODAY()),EDATE(DATE(2026,3,1),1))-MAX($J10,DATE(2026,3,1)))*$G10/($K10-$J10))) -> 7725.9712 | O10: =IF(OR($J10="",$K10="",$G10=""),0,IF($K10<=$J10,IF(AND($J10>=DATE(2026,4,1),$J10<EDATE(DATE(2026,4,1),1),TODAY()>=$J10),$G10,0),MAX(0,MIN(IF(TODAY()>$K10,$K10,TODAY()),EDATE(DATE(2026,4,1),1))-MAX($J10,DATE(2026,4,1)))*$G10/($K10-$J10))) -> 7476.7463 | P10: =IF(OR($J10="",$K10="",$G10=""),0,IF($K10<=$J10,IF(AND($J10>=DATE(2026,5,1),$J10<EDATE(DATE(2026,5,1),1),TODAY()>=$J10),$G10,0),MAX(0,MIN(IF(TODAY()>$K10,$K10,TODAY()),EDATE(DATE(2026,5,1),1))-MAX($J10,DATE(2026,5,1)))*$G10/($K10-$J10))) -> 7725.9712 | Q10: =IF(OR($J10="",$K10="",$G10=""),0,IF($K10<=$J10,IF(AND($J10>=DATE(2026,6,1),$J10<EDATE(DATE(2026,5,1),1),TODAY()>=$J10),$G10,0),MAX(0,MIN(IF(TODAY()>$K10,$K10,TODAY()),EDATE(DATE(2026,6,1),1))-MAX($J10,DATE(2026,6,1)))*$G10/($K10-$J10))) -> 7227.5214 | T10: =SUMIF(Tableau!$A:$A,$A10,Tableau!G:G) -> #N/A | U10: =SUMIF(Tableau!$A:$A,$A10,Tableau!H:H) -> #N/A | V10: =SUMIF(Tableau!$A:$A,$A10,Tableau!I:I) -> #N/A | W10: =SUMIF(Tableau!$A:$A,$A10,Tableau!J:J) -> #N/A | AL10: Total | AV10: =SUM(AP10:AU10) -> #N/A | CF10: =IFERROR(BT10/BZ10,0) -> 0 | CG10: =IFERROR(BU10/CA10,0) -> 0 | CH10: =IFERROR(BV10/CB10,0) -> 0 | CI10: =IFERROR(BW10/CC10,0) -> 0 | CJ10: =IFERROR(BX10/CD10,0) -> 0 | CK10: =IFERROR(BY10/CE10,0) -> 0
A11: =Data2026!A17 -> coincodex | B11: =Data2026!B17 -> 46081 | C11: =Data2026!C17 -> Fixed | D11: =Data2026!D17 -> coincodex | E11: =Data2026!E17 -> Nini_B | F11: =Data2026!F17 -> 46081 | G11: =Data2026!G17 -> 8586.6 | H11: =Data2026!H17 -> Finished | ... K11: =Data2026!K17 -> 46111 | L11: =IF(OR($J11="",$K11="",$G11=""),0,IF($K11<=$J11,IF(AND($J11>=DATE(2026,1,1),$J11<EDATE(DATE(2026,1,1),1),TODAY()>=$J11),$G11,0),MAX(0,MIN(IF(TODAY()>$K11,$K11,TODAY()),EDATE(DATE(2026,1,1),1))-MAX($J11,DATE(2026,1,1)))*$G11/($K11-$J11))) -> 0 | M11: =IF(OR($J11="",$K11="",$G11=""),0,IF($K11<=$J11,IF(AND($J11>=DATE(2026,2,1),$J11<EDATE(DATE(2026,2,1),1),TODAY()>=$J11),$G11,0),MAX(0,MIN(IF(TODAY()>$K11,$K11,TODAY()),EDATE(DATE(2026,2,1),1))-MAX($J11,DATE(2026,2,1)))*$G11/($K11-$J11))) -> 286.22 | N11: =IF(OR($J11="",$K11="",$G11=""),0,IF($K11<=$J11,IF(AND($J11>=DATE(2026,3,1),$J11<EDATE(DATE(2026,3,1),1),TODAY()>=$J11),$G11,0),MAX(0,MIN(IF(TODAY()>$K11,$K11,TODAY()),EDATE(DATE(2026,3,1),1))-MAX($J11,DATE(2026,3,1)))*$G11/($K11-$J11))) -> 8300.38 | O11: =IF(OR($J11="",$K11="",$G11=""),0,IF($K11<=$J11,IF(AND($J11>=DATE(2026,4,1),$J11<EDATE(DATE(2026,4,1),1),TODAY()>=$J11),$G11,0),MAX(0,MIN(IF(TODAY()>$K11,$K11,TODAY()),EDATE(DATE(2026,4,1),1))-MAX($J11,DATE(2026,4,1)))*$G11/($K11-$J11))) -> 0 | P11: =IF(OR($J11="",$K11="",$G11=""),0,IF($K11<=$J11,IF(AND($J11>=DATE(2026,5,1),$J11<EDATE(DATE(2026,5,1),1),TODAY()>=$J11),$G11,0),MAX(0,MIN(IF(TODAY()>$K11,$K11,TODAY()),EDATE(DATE(2026,5,1),1))-MAX($J11,DATE(2026,5,1)))*$G11/($K11-$J11))) -> 0 | Q11: =IF(OR($J11="",$K11="",$G11=""),0,IF($K11<=$J11,IF(AND($J11>=DATE(2026,6,1),$J11<EDATE(DATE(2026,5,1),1),TODAY()>=$J11),$G11,0),MAX(0,MIN(IF(TODAY()>$K11,$K11,TODAY()),EDATE(DATE(2026,6,1),1))-MAX($J11,DATE(2026,6,1)))*$G11/($K11-$J11))) -> 0 | R11: =SUMIF(Tableau!$A:$A,$A11,Tableau!E:E) -> #N/A | S11: =SUMIF(Tableau!$A:$A,$A11,Tableau!F:F) -> #N/A | T11: =SUMIF(Tableau!$A:$A,$A11,Tableau!G:G) -> #N/A | U11: =SUMIF(Tableau!$A:$A,$A11,Tableau!H:H) -> #N/A | V11: =SUMIF(Tableau!$A:$A,$A11,Tableau!I:I) -> #N/A | W11: =SUMIF(Tableau!$A:$A,$A11,Tableau!J:J) -> #N/A | X11: =SUMIF(Tableau!$A:$A,$A11,Tableau!P:P) -> #N/A | Y11: =SUMIF(Tableau!$A:$A,$A11,Tableau!Q:Q) -> #N/A | Z11: =SUMIF(Tableau!$A:$A,$A11,Tableau!R:R) -> #N/A | AA11: =SUMIF(Tableau!$A:$A,$A11,Tableau!S:S) -> #N/A | AB11: =SUMIF(Tableau!$A:$A,$A11,Tableau!T:T) -> #N/A | AC11: =SUMIF(Tableau!$A:$A,$A11,Tableau!U:U) -> #N/A | AL11: =SUM(AF11:AK11) -> 0 | CF11: =IFERROR(BT11/BZ11,0) -> 0 | CG11: =IFERROR(BU11/CA11,0) -> 0 | CH11: =IFERROR(BV11/CB11,0) -> 0 | CI11: =IFERROR(BW11/CC11,0) -> 0 | CJ11: =IFERROR(BX11/CD11,0) -> 0 | CK11: =IFERROR(BY11/CE11,0) -> 0
A12: =Data2026!A18 -> rocketlink | B12: =Data2026!B18 -> 46082 | C12: =Data2026!C18 -> Fixed | D12: =Data2026!D18 -> rocketlink | E12: =Data2026!E18 -> Nugi | F12: =Data2026!F18 -> 46082 | G12: =Data2026!G18 -> 1500 | H12: =Data2026!H18 -> Finished | ... K12: =Data2026!K18 -> 46112 | L12: =IF(OR($J12="",$K12="",$G12=""),0,IF($K12<=$J12,IF(AND($J12>=DATE(2026,1,1),$J12<EDATE(DATE(2026,1,1),1),TODAY()>=$J12),$G12,0),MAX(0,MIN(IF(TODAY()>$K12,$K12,TODAY()),EDATE(DATE(2026,1,1),1))-MAX($J12,DATE(2026,1,1)))*$G12/($K12-$J12))) -> 0 | M12: =IF(OR($J12="",$K12="",$G12=""),0,IF($K12<=$J12,IF(AND($J12>=DATE(2026,2,1),$J12<EDATE(DATE(2026,2,1),1),TODAY()>=$J12),$G12,0),MAX(0,MIN(IF(TODAY()>$K12,$K12,TODAY()),EDATE(DATE(2026,2,1),1))-MAX($J12,DATE(2026,2,1)))*$G12/($K12-$J12))) -> 0 | N12: =IF(OR($J12="",$K12="",$G12=""),0,IF($K12<=$J12,IF(AND($J12>=DATE(2026,3,1),$J12<EDATE(DATE(2026,3,1),1),TODAY()>=$J12),$G12,0),MAX(0,MIN(IF(TODAY()>$K12,$K12,TODAY()),EDATE(DATE(2026,3,1),1))-MAX($J12,DATE(2026,3,1)))*$G12/($K12-$J12))) -> 1500 | O12: =IF(OR($J12="",$K12="",$G12=""),0,IF($K12<=$J12,IF(AND($J12>=DATE(2026,4,1),$J12<EDATE(DATE(2026,4,1),1),TODAY()>=$J12),$G12,0),MAX(0,MIN(IF(TODAY()>$K12,$K12,TODAY()),EDATE(DATE(2026,4,1),1))-MAX($J12,DATE(2026,4,1)))*$G12/($K12-$J12))) -> 0 | P12: =IF(OR($J12="",$K12="",$G12=""),0,IF($K12<=$J12,IF(AND($J12>=DATE(2026,5,1),$J12<EDATE(DATE(2026,5,1),1),TODAY()>=$J12),$G12,0),MAX(0,MIN(IF(TODAY()>$K12,$K12,TODAY()),EDATE(DATE(2026,5,1),1))-MAX($J12,DATE(2026,5,1)))*$G12/($K12-$J12))) -> 0 | Q12: =IF(OR($J12="",$K12="",$G12=""),0,IF($K12<=$J12,IF(AND($J12>=DATE(2026,6,1),$J12<EDATE(DATE(2026,5,1),1),TODAY()>=$J12),$G12,0),MAX(0,MIN(IF(TODAY()>$K12,$K12,TODAY()),EDATE(DATE(2026,6,1),1))-MAX($J12,DATE(2026,6,1)))*$G12/($K12-$J12))) -> 0 | R12: =SUMIF(Tableau!$A:$A,$A12,Tableau!E:E) -> #N/A | S12: =SUMIF(Tableau!$A:$A,$A12,Tableau!F:F) -> #N/A | T12: =SUMIF(Tableau!$A:$A,$A12,Tableau!G:G) -> #N/A | U12: =SUMIF(Tableau!$A:$A,$A12,Tableau!H:H) -> #N/A | V12: =SUMIF(Tableau!$A:$A,$A12,Tableau!I:I) -> #N/A | W12: =SUMIF(Tableau!$A:$A,$A12,Tableau!J:J) -> #N/A | X12: =SUMIF(Tableau!$A:$A,$A12,Tableau!P:P) -> #N/A | Y12: =SUMIF(Tableau!$A:$A,$A12,Tableau!Q:Q) -> #N/A | Z12: =SUMIF(Tableau!$A:$A,$A12,Tableau!R:R) -> #N/A | AA12: =SUMIF(Tableau!$A:$A,$A12,Tableau!S:S) -> #N/A | AB12: =SUMIF(Tableau!$A:$A,$A12,Tableau!T:T) -> #N/A | AC12: =SUMIF(Tableau!$A:$A,$A12,Tableau!U:U) -> #N/A | AL12: =SUM(AF12:AK12) -> 0 | CF12: =IFERROR(BT12/BZ12,0) -> 0 | CG12: =IFERROR(BU12/CA12,0) -> 0 | CH12: =IFERROR(BV12/CB12,0) -> 0 | CI12: =IFERROR(BW12/CC12,0) -> 0 | CJ12: =IFERROR(BX12/CD12,0) -> 0 | CK12: =IFERROR(BY12/CE12,0) -> 0
A13: =Data2026!A19 -> bwisemedia | B13: =Data2026!B19 -> 46085 | C13: =Data2026!C19 -> Fixed | D13: =Data2026!D19 -> bwisemedia | E13: =Data2026!E19 -> Elene_Gh | F13: =Data2026!F19 -> 46085 | G13: =Data2026!G19 -> 3062.32 | H13: =Data2026!H19 -> Finished | ... K13: =Data2026!K19 -> 46115 | L13: =IF(OR($J13="",$K13="",$G13=""),0,IF($K13<=$J13,IF(AND($J13>=DATE(2026,1,1),$J13<EDATE(DATE(2026,1,1),1),TODAY()>=$J13),$G13,0),MAX(0,MIN(IF(TODAY()>$K13,$K13,TODAY()),EDATE(DATE(2026,1,1),1))-MAX($J13,DATE(2026,1,1)))*$G13/($K13-$J13))) -> 0 | M13: =IF(OR($J13="",$K13="",$G13=""),0,IF($K13<=$J13,IF(AND($J13>=DATE(2026,2,1),$J13<EDATE(DATE(2026,2,1),1),TODAY()>=$J13),$G13,0),MAX(0,MIN(IF(TODAY()>$K13,$K13,TODAY()),EDATE(DATE(2026,2,1),1))-MAX($J13,DATE(2026,2,1)))*$G13/($K13-$J13))) -> 0 | N13: =IF(OR($J13="",$K13="",$G13=""),0,IF($K13<=$J13,IF(AND($J13>=DATE(2026,3,1),$J13<EDATE(DATE(2026,3,1),1),TODAY()>=$J13),$G13,0),MAX(0,MIN(IF(TODAY()>$K13,$K13,TODAY()),EDATE(DATE(2026,3,1),1))-MAX($J13,DATE(2026,3,1)))*$G13/($K13-$J13))) -> 2858.1653 | O13: =IF(OR($J13="",$K13="",$G13=""),0,IF($K13<=$J13,IF(AND($J13>=DATE(2026,4,1),$J13<EDATE(DATE(2026,4,1),1),TODAY()>=$J13),$G13,0),MAX(0,MIN(IF(TODAY()>$K13,$K13,TODAY()),EDATE(DATE(2026,4,1),1))-MAX($J13,DATE(2026,4,1)))*$G13/($K13-$J13))) -> 204.15467 | P13: =IF(OR($J13="",$K13="",$G13=""),0,IF($K13<=$J13,IF(AND($J13>=DATE(2026,5,1),$J13<EDATE(DATE(2026,5,1),1),TODAY()>=$J13),$G13,0),MAX(0,MIN(IF(TODAY()>$K13,$K13,TODAY()),EDATE(DATE(2026,5,1),1))-MAX($J13,DATE(2026,5,1)))*$G13/($K13-$J13))) -> 0 | Q13: =IF(OR($J13="",$K13="",$G13=""),0,IF($K13<=$J13,IF(AND($J13>=DATE(2026,6,1),$J13<EDATE(DATE(2026,5,1),1),TODAY()>=$J13),$G13,0),MAX(0,MIN(IF(TODAY()>$K13,$K13,TODAY()),EDATE(DATE(2026,6,1),1))-MAX($J13,DATE(2026,6,1)))*$G13/($K13-$J13))) -> 0 | R13: =SUMIF(Tableau!$A:$A,$A13,Tableau!E:E) -> #N/A | S13: =SUMIF(Tableau!$A:$A,$A13,Tableau!F:F) -> #N/A | T13: =SUMIF(Tableau!$A:$A,$A13,Tableau!G:G) -> #N/A | U13: =SUMIF(Tableau!$A:$A,$A13,Tableau!H:H) -> #N/A | V13: =SUMIF(Tableau!$A:$A,$A13,Tableau!I:I) -> #N/A | W13: =SUMIF(Tableau!$A:$A,$A13,Tableau!J:J) -> #N/A | X13: =SUMIF(Tableau!$A:$A,$A13,Tableau!P:P) -> #N/A | Y13: =SUMIF(Tableau!$A:$A,$A13,Tableau!Q:Q) -> #N/A | Z13: =SUMIF(Tableau!$A:$A,$A13,Tableau!R:R) -> #N/A | AA13: =SUMIF(Tableau!$A:$A,$A13,Tableau!S:S) -> #N/A | AB13: =SUMIF(Tableau!$A:$A,$A13,Tableau!T:T) -> #N/A | AC13: =SUMIF(Tableau!$A:$A,$A13,Tableau!U:U) -> #N/A | AL13: =SUM(AF13:AK13) -> 0 | AV13: Total | CF13: =IFERROR(BT13/BZ13,0) -> 0 | CG13: =IFERROR(BU13/CA13,0) -> 0 | CH13: =IFERROR(BV13/CB13,0) -> 0 | CI13: =IFERROR(BW13/CC13,0) -> 0 | CJ13: =IFERROR(BX13/CD13,0) -> 0 | CK13: =IFERROR(BY13/CE13,0) -> 0
A14: =Data2026!A20 -> andriiparfenov1 | B14: =Data2026!B20 -> 46091 | C14: =Data2026!C20 -> CPA | D14: =Data2026!D20 -> andriiparfenov1 | E14: =Data2026!E20 -> Elene_Gh | F14: =Data2026!F20 -> 46091 | G14: =Data2026!G20 -> 400 | H14: =Data2026!H20 -> Finished | ... K14: =Data2026!K20 -> 46121 | L14: =IF(OR($J14="",$K14="",$G14=""),0,IF($K14<=$J14,IF(AND($J14>=DATE(2026,1,1),$J14<EDATE(DATE(2026,1,1),1),TODAY()>=$J14),$G14,0),MAX(0,MIN(IF(TODAY()>$K14,$K14,TODAY()),EDATE(DATE(2026,1,1),1))-MAX($J14,DATE(2026,1,1)))*$G14/($K14-$J14))) -> 0 | M14: =IF(OR($J14="",$K14="",$G14=""),0,IF($K14<=$J14,IF(AND($J14>=DATE(2026,2,1),$J14<EDATE(DATE(2026,2,1),1),TODAY()>=$J14),$G14,0),MAX(0,MIN(IF(TODAY()>$K14,$K14,TODAY()),EDATE(DATE(2026,2,1),1))-MAX($J14,DATE(2026,2,1)))*$G14/($K14-$J14))) -> 0 | N14: =IF(OR($J14="",$K14="",$G14=""),0,IF($K14<=$J14,IF(AND($J14>=DATE(2026,3,1),$J14<EDATE(DATE(2026,3,1),1),TODAY()>=$J14),$G14,0),MAX(0,MIN(IF(TODAY()>$K14,$K14,TODAY()),EDATE(DATE(2026,3,1),1))-MAX($J14,DATE(2026,3,1)))*$G14/($K14-$J14))) -> 293.33333 | O14: =IF(OR($J14="",$K14="",$G14=""),0,IF($K14<=$J14,IF(AND($J14>=DATE(2026,4,1),$J14<EDATE(DATE(2026,4,1),1),TODAY()>=$J14),$G14,0),MAX(0,MIN(IF(TODAY()>$K14,$K14,TODAY()),EDATE(DATE(2026,4,1),1))-MAX($J14,DATE(2026,4,1)))*$G14/($K14-$J14))) -> 106.66667 | P14: =IF(OR($J14="",$K14="",$G14=""),0,IF($K14<=$J14,IF(AND($J14>=DATE(2026,5,1),$J14<EDATE(DATE(2026,5,1),1),TODAY()>=$J14),$G14,0),MAX(0,MIN(IF(TODAY()>$K14,$K14,TODAY()),EDATE(DATE(2026,5,1),1))-MAX($J14,DATE(2026,5,1)))*$G14/($K14-$J14))) -> 0 | Q14: =IF(OR($J14="",$K14="",$G14=""),0,IF($K14<=$J14,IF(AND($J14>=DATE(2026,6,1),$J14<EDATE(DATE(2026,5,1),1),TODAY()>=$J14),$G14,0),MAX(0,MIN(IF(TODAY()>$K14,$K14,TODAY()),EDATE(DATE(2026,6,1),1))-MAX($J14,DATE(2026,6,1)))*$G14/($K14-$J14))) -> 0 | R14: =SUMIF(Tableau!$A:$A,$A14,Tableau!E:E) -> #N/A | S14: =SUMIF(Tableau!$A:$A,$A14,Tableau!F:F) -> #N/A | T14: =SUMIF(Tableau!$A:$A,$A14,Tableau!G:G) -> #N/A | U14: =SUMIF(Tableau!$A:$A,$A14,Tableau!H:H) -> #N/A | V14: =SUMIF(Tableau!$A:$A,$A14,Tableau!I:I) -> #N/A | W14: =SUMIF(Tableau!$A:$A,$A14,Tableau!J:J) -> #N/A | X14: =SUMIF(Tableau!$A:$A,$A14,Tableau!P:P) -> #N/A | Y14: =SUMIF(Tableau!$A:$A,$A14,Tableau!Q:Q) -> #N/A | Z14: =SUMIF(Tableau!$A:$A,$A14,Tableau!R:R) -> #N/A | AA14: =SUMIF(Tableau!$A:$A,$A14,Tableau!S:S) -> #N/A | AB14: =SUMIF(Tableau!$A:$A,$A14,Tableau!T:T) -> #N/A | AC14: =SUMIF(Tableau!$A:$A,$A14,Tableau!U:U) -> #N/A | AL14: =SUM(AF14:AK14) -> 0 | AV14: =SUM(AP14:AU14) -> 0 | BH14: INFLUENCE CPA | CF14: =IFERROR(BT14/BZ14,0) -> 0 | CG14: =IFERROR(BU14/CA14,0) -> 0 | CH14: =IFERROR(BV14/CB14,0) -> 0 | CI14: =IFERROR(BW14/CC14,0) -> 0 | CJ14: =IFERROR(BX14/CD14,0) -> 0 | CK14: =IFERROR(BY14/CE14,0) -> 0
A15: =Data2026!A21 -> DappCentre | B15: =Data2026!B21 -> 46093 | C15: =Data2026!C21 -> Fixed | D15: =Data2026!D21 -> DappCentre | E15: =Data2026!E21 -> Nini_B | F15: =Data2026!F21 -> 46093 | G15: =Data2026!G21 -> 1423.29 | H15: =Data2026!H21 -> Finished | ... K15: =Data2026!K21 -> 46213 | L15: =IF(OR($J15="",$K15="",$G15=""),0,IF($K15<=$J15,IF(AND($J15>=DATE(2026,1,1),$J15<EDATE(DATE(2026,1,1),1),TODAY()>=$J15),$G15,0),MAX(0,MIN(IF(TODAY()>$K15,$K15,TODAY()),EDATE(DATE(2026,1,1),1))-MAX($J15,DATE(2026,1,1)))*$G15/($K15-$J15))) -> 0 | M15: =IF(OR($J15="",$K15="",$G15=""),0,IF($K15<=$J15,IF(AND($J15>=DATE(2026,2,1),$J15<EDATE(DATE(2026,2,1),1),TODAY()>=$J15),$G15,0),MAX(0,MIN(IF(TODAY()>$K15,$K15,TODAY()),EDATE(DATE(2026,2,1),1))-MAX($J15,DATE(2026,2,1)))*$G15/($K15-$J15))) -> 0 | N15: =IF(OR($J15="",$K15="",$G15=""),0,IF($K15<=$J15,IF(AND($J15>=DATE(2026,3,1),$J15<EDATE(DATE(2026,3,1),1),TODAY()>=$J15),$G15,0),MAX(0,MIN(IF(TODAY()>$K15,$K15,TODAY()),EDATE(DATE(2026,3,1),1))-MAX($J15,DATE(2026,3,1)))*$G15/($K15-$J15))) -> 237.215 | O15: =IF(OR($J15="",$K15="",$G15=""),0,IF($K15<=$J15,IF(AND($J15>=DATE(2026,4,1),$J15<EDATE(DATE(2026,4,1),1),TODAY()>=$J15),$G15,0),MAX(0,MIN(IF(TODAY()>$K15,$K15,TODAY()),EDATE(DATE(2026,4,1),1))-MAX($J15,DATE(2026,4,1)))*$G15/($K15-$J15))) -> 355.8225 | P15: =IF(OR($J15="",$K15="",$G15=""),0,IF($K15<=$J15,IF(AND($J15>=DATE(2026,5,1),$J15<EDATE(DATE(2026,5,1),1),TODAY()>=$J15),$G15,0),MAX(0,MIN(IF(TODAY()>$K15,$K15,TODAY()),EDATE(DATE(2026,5,1),1))-MAX($J15,DATE(2026,5,1)))*$G15/($K15-$J15))) -> 367.68325 | Q15: =IF(OR($J15="",$K15="",$G15=""),0,IF($K15<=$J15,IF(AND($J15>=DATE(2026,6,1),$J15<EDATE(DATE(2026,5,1),1),TODAY()>=$J15),$G15,0),MAX(0,MIN(IF(TODAY()>$K15,$K15,TODAY()),EDATE(DATE(2026,6,1),1))-MAX($J15,DATE(2026,6,1)))*$G15/($K15-$J15))) -> 355.8225 | R15: =SUMIF(Tableau!$A:$A,$A15,Tableau!E:E) -> #N/A | S15: =SUMIF(Tableau!$A:$A,$A15,Tableau!F:F) -> #N/A | T15: =SUMIF(Tableau!$A:$A,$A15,Tableau!G:G) -> #N/A | U15: =SUMIF(Tableau!$A:$A,$A15,Tableau!H:H) -> #N/A | V15: =SUMIF(Tableau!$A:$A,$A15,Tableau!I:I) -> #N/A | W15: =SUMIF(Tableau!$A:$A,$A15,Tableau!J:J) -> #N/A | X15: =SUMIF(Tableau!$A:$A,$A15,Tableau!P:P) -> #N/A | Y15: =SUMIF(Tableau!$A:$A,$A15,Tableau!Q:Q) -> #N/A | Z15: =SUMIF(Tableau!$A:$A,$A15,Tableau!R:R) -> #N/A | AA15: =SUMIF(Tableau!$A:$A,$A15,Tableau!S:S) -> #N/A | AB15: =SUMIF(Tableau!$A:$A,$A15,Tableau!T:T) -> #N/A | AC15: =SUMIF(Tableau!$A:$A,$A15,Tableau!U:U) -> #N/A | AL15: =SUM(AF15:AK15) -> 0 | AV15: =SUM(AP15:AU15) -> 0 | BF15: Total | BI15: January CPA | BJ15: February CPA | BK15: March CPA | BL15: April CPA | BM15: May CPA | BN15: June CPA | BO15: Total | CF15: =IFERROR(BT15/BZ15,0) -> 0 | CG15: =IFERROR(BU15/CA15,0) -> 0 | CH15: =IFERROR(BV15/CB15,0) -> 0 | CI15: =IFERROR(BW15/CC15,0) -> 0 | CJ15: =IFERROR(BX15/CD15,0) -> 0 | CK15: =IFERROR(BY15/CE15,0) -> 0
A16: =Data2026!A22 -> Ricardoc24 | B16: =Data2026!B22 -> 46094 | C16: =Data2026!C22 -> Fixed | D16: =Data2026!D22 -> Ricardoc24 | E16: =Data2026!E22 -> Nini_B | F16: =Data2026!F22 -> 46094 | G16: =Data2026!G22 | H16: =Data2026!H22 -> Finished | ... K16: =Data2026!K22 -> 46124 | L16: =IF(OR($J16="",$K16="",$G16=""),0,IF($K16<=$J16,IF(AND($J16>=DATE(2026,1,1),$J16<EDATE(DATE(2026,1,1),1),TODAY()>=$J16),$G16,0),MAX(0,MIN(IF(TODAY()>$K16,$K16,TODAY()),EDATE(DATE(2026,1,1),1))-MAX($J16,DATE(2026,1,1)))*$G16/($K16-$J16))) -> 0 | M16: =IF(OR($J16="",$K16="",$G16=""),0,IF($K16<=$J16,IF(AND($J16>=DATE(2026,2,1),$J16<EDATE(DATE(2026,2,1),1),TODAY()>=$J16),$G16,0),MAX(0,MIN(IF(TODAY()>$K16,$K16,TODAY()),EDATE(DATE(2026,2,1),1))-MAX($J16,DATE(2026,2,1)))*$G16/($K16-$J16))) -> 0 | N16: =IF(OR($J16="",$K16="",$G16=""),0,IF($K16<=$J16,IF(AND($J16>=DATE(2026,3,1),$J16<EDATE(DATE(2026,3,1),1),TODAY()>=$J16),$G16,0),MAX(0,MIN(IF(TODAY()>$K16,$K16,TODAY()),EDATE(DATE(2026,3,1),1))-MAX($J16,DATE(2026,3,1)))*$G16/($K16-$J16))) -> 0 | O16: =IF(OR($J16="",$K16="",$G16=""),0,IF($K16<=$J16,IF(AND($J16>=DATE(2026,4,1),$J16<EDATE(DATE(2026,4,1),1),TODAY()>=$J16),$G16,0),MAX(0,MIN(IF(TODAY()>$K16,$K16,TODAY()),EDATE(DATE(2026,4,1),1))-MAX($J16,DATE(2026,4,1)))*$G16/($K16-$J16))) -> 0 | P16: =IF(OR($J16="",$K16="",$G16=""),0,IF($K16<=$J16,IF(AND($J16>=DATE(2026,5,1),$J16<EDATE(DATE(2026,5,1),1),TODAY()>=$J16),$G16,0),MAX(0,MIN(IF(TODAY()>$K16,$K16,TODAY()),EDATE(DATE(2026,5,1),1))-MAX($J16,DATE(2026,5,1)))*$G16/($K16-$J16))) -> 0 | Q16: =IF(OR($J16="",$K16="",$G16=""),0,IF($K16<=$J16,IF(AND($J16>=DATE(2026,6,1),$J16<EDATE(DATE(2026,5,1),1),TODAY()>=$J16),$G16,0),MAX(0,MIN(IF(TODAY()>$K16,$K16,TODAY()),EDATE(DATE(2026,6,1),1))-MAX($J16,DATE(2026,6,1)))*$G16/($K16-$J16))) -> 0 | R16: =SUMIF(Tableau!$A:$A,$A16,Tableau!E:E) -> #N/A | S16: =SUMIF(Tableau!$A:$A,$A16,Tableau!F:F) -> #N/A | T16: =SUMIF(Tableau!$A:$A,$A16,Tableau!G:G) -> #N/A | U16: =SUMIF(Tableau!$A:$A,$A16,Tableau!H:H) -> #N/A | V16: =SUMIF(Tableau!$A:$A,$A16,Tableau!I:I) -> #N/A | W16: =SUMIF(Tableau!$A:$A,$A16,Tableau!J:J) -> #N/A | X16: =SUMIF(Tableau!$A:$A,$A16,Tableau!P:P) -> #N/A | Y16: =SUMIF(Tableau!$A:$A,$A16,Tableau!Q:Q) -> #N/A | Z16: =SUMIF(Tableau!$A:$A,$A16,Tableau!R:R) -> #N/A | AA16: =SUMIF(Tableau!$A:$A,$A16,Tableau!S:S) -> #N/A | AB16: =SUMIF(Tableau!$A:$A,$A16,Tableau!T:T) -> #N/A | AC16: =SUMIF(Tableau!$A:$A,$A16,Tableau!U:U) -> #N/A | AL16: =SUM(AF16:AK16) -> 0 | AV16: =SUM(AP16:AU16) -> 686.9 | BF16: =SUM(AZ16:BE16) -> #N/A | BH16: migzparcerias | BI16: 0 | BJ16: 0 | BK16: 105.63063 | BL16: 86.731392 | BM16: 0 | BN16: 0 | BO16: 48.976608 | CF16: =IFERROR(BT16/BZ16,0) -> 0 | CG16: =IFERROR(BU16/CA16,0) -> 0 | CH16: =IFERROR(BV16/CB16,0) -> 0 | CI16: =IFERROR(BW16/CC16,0) -> 0 | CJ16: =IFERROR(BX16/CD16,0) -> 0 | CK16: =IFERROR(BY16/CE16,0) -> 0
A17: =Data2026!A23 -> Valek | B17: =Data2026!B23 -> 46094 | C17: =Data2026!C23 -> Fixed | D17: =Data2026!D23 -> Valek | E17: =Data2026!E23 -> Nini_B | F17: =Data2026!F23 -> 46094 | G17: =Data2026!G23 -> 2700.59 | H17: =Data2026!H23 -> Finished | ... K17: =Data2026!K23 -> 46124 | L17: =IF(OR($J17="",$K17="",$G17=""),0,IF($K17<=$J17,IF(AND($J17>=DATE(2026,1,1),$J17<EDATE(DATE(2026,1,1),1),TODAY()>=$J17),$G17,0),MAX(0,MIN(IF(TODAY()>$K17,$K17,TODAY()),EDATE(DATE(2026,1,1),1))-MAX($J17,DATE(2026,1,1)))*$G17/($K17-$J17))) -> 0 | M17: =IF(OR($J17="",$K17="",$G17=""),0,IF($K17<=$J17,IF(AND($J17>=DATE(2026,2,1),$J17<EDATE(DATE(2026,2,1),1),TODAY()>=$J17),$G17,0),MAX(0,MIN(IF(TODAY()>$K17,$K17,TODAY()),EDATE(DATE(2026,2,1),1))-MAX($J17,DATE(2026,2,1)))*$G17/($K17-$J17))) -> 0 | N17: =IF(OR($J17="",$K17="",$G17=""),0,IF($K17<=$J17,IF(AND($J17>=DATE(2026,3,1),$J17<EDATE(DATE(2026,3,1),1),TODAY()>=$J17),$G17,0),MAX(0,MIN(IF(TODAY()>$K17,$K17,TODAY()),EDATE(DATE(2026,3,1),1))-MAX($J17,DATE(2026,3,1)))*$G17/($K17-$J17))) -> 1710.3737 | O17: =IF(OR($J17="",$K17="",$G17=""),0,IF($K17<=$J17,IF(AND($J17>=DATE(2026,4,1),$J17<EDATE(DATE(2026,4,1),1),TODAY()>=$J17),$G17,0),MAX(0,MIN(IF(TODAY()>$K17,$K17,TODAY()),EDATE(DATE(2026,4,1),1))-MAX($J17,DATE(2026,4,1)))*$G17/($K17-$J17))) -> 990.21633 | P17: =IF(OR($J17="",$K17="",$G17=""),0,IF($K17<=$J17,IF(AND($J17>=DATE(2026,5,1),$J17<EDATE(DATE(2026,5,1),1),TODAY()>=$J17),$G17,0),MAX(0,MIN(IF(TODAY()>$K17,$K17,TODAY()),EDATE(DATE(2026,5,1),1))-MAX($J17,DATE(2026,5,1)))*$G17/($K17-$J17))) -> 0 | Q17: =IF(OR($J17="",$K17="",$G17=""),0,IF($K17<=$J17,IF(AND($J17>=DATE(2026,6,1),$J17<EDATE(DATE(2026,5,1),1),TODAY()>=$J17),$G17,0),MAX(0,MIN(IF(TODAY()>$K17,$K17,TODAY()),EDATE(DATE(2026,6,1),1))-MAX($J17,DATE(2026,6,1)))*$G17/($K17-$J17))) -> 0 | R17: =SUMIF(Tableau!$A:$A,$A17,Tableau!E:E) -> #N/A | S17: =SUMIF(Tableau!$A:$A,$A17,Tableau!F:F) -> #N/A | T17: =SUMIF(Tableau!$A:$A,$A17,Tableau!G:G) -> #N/A | U17: =SUMIF(Tableau!$A:$A,$A17,Tableau!H:H) -> #N/A | V17: =SUMIF(Tableau!$A:$A,$A17,Tableau!I:I) -> #N/A | W17: =SUMIF(Tableau!$A:$A,$A17,Tableau!J:J) -> #N/A | X17: =SUMIF(Tableau!$A:$A,$A17,Tableau!P:P) -> #N/A | Y17: =SUMIF(Tableau!$A:$A,$A17,Tableau!Q:Q) -> #N/A | Z17: =SUMIF(Tableau!$A:$A,$A17,Tableau!R:R) -> #N/A | AA17: =SUMIF(Tableau!$A:$A,$A17,Tableau!S:S) -> #N/A | AB17: =SUMIF(Tableau!$A:$A,$A17,Tableau!T:T) -> #N/A | AC17: =SUMIF(Tableau!$A:$A,$A17,Tableau!U:U) -> #N/A | AL17: =SUM(AF17:AK17) -> 0 | AV17: =SUM(AP17:AU17) -> 580.67 | BF17: =SUM(AZ17:BE17) -> #N/A | BH17: Naqo | BI17: 0 | BJ17: 0 | BK17: 0 | BL17: 0 | BM17: 0 | BN17: 11.860625 | BO17: 11.860625 | CF17: =IFERROR(BT17/BZ17,0) -> 0 | CG17: =IFERROR(BU17/CA17,0) -> 0 | CH17: =IFERROR(BV17/CB17,0) -> 0 | CI17: =IFERROR(BW17/CC17,0) -> 0 | CJ17: =IFERROR(BX17/CD17,0) -> 0 | CK17: =IFERROR(BY17/CE17,0) -> 0
A18: =Data2026!A24 -> trimics2 | B18: =Data2026!B24 -> 46094 | C18: =Data2026!C24 -> Fixed | D18: =Data2026!D24 -> trimics2 | E18: =Data2026!E24 -> Nini_B | F18: =Data2026!F24 -> 46094 | G18: =Data2026!G24 -> 3479.61 | H18: =Data2026!H24 -> Finished | ... K18: =Data2026!K24 -> 46124 | L18: =IF(OR($J18="",$K18="",$G18=""),0,IF($K18<=$J18,IF(AND($J18>=DATE(2026,1,1),$J18<EDATE(DATE(2026,1,1),1),TODAY()>=$J18),$G18,0),MAX(0,MIN(IF(TODAY()>$K18,$K18,TODAY()),EDATE(DATE(2026,1,1),1))-MAX($J18,DATE(2026,1,1)))*$G18/($K18-$J18))) -> 0 | M18: =IF(OR($J18="",$K18="",$G18=""),0,IF($K18<=$J18,IF(AND($J18>=DATE(2026,2,1),$J18<EDATE(DATE(2026,2,1),1),TODAY()>=$J18),$G18,0),MAX(0,MIN(IF(TODAY()>$K18,$K18,TODAY()),EDATE(DATE(2026,2,1),1))-MAX($J18,DATE(2026,2,1)))*$G18/($K18-$J18))) -> 0 | N18: =IF(OR($J18="",$K18="",$G18=""),0,IF($K18<=$J18,IF(AND($J18>=DATE(2026,3,1),$J18<EDATE(DATE(2026,3,1),1),TODAY()>=$J18),$G18,0),MAX(0,MIN(IF(TODAY()>$K18,$K18,TODAY()),EDATE(DATE(2026,3,1),1))-MAX($J18,DATE(2026,3,1)))*$G18/($K18-$J18))) -> 2203.753 | O18: =IF(OR($J18="",$K18="",$G18=""),0,IF($K18<=$J18,IF(AND($J18>=DATE(2026,4,1),$J18<EDATE(DATE(2026,4,1),1),TODAY()>=$J18),$G18,0),MAX(0,MIN(IF(TODAY()>$K18,$K18,TODAY()),EDATE(DATE(2026,4,1),1))-MAX($J18,DATE(2026,4,1)))*$G18/($K18-$J18))) -> 1275.857 | P18: =IF(OR($J18="",$K18="",$G18=""),0,IF($K18<=$J18,IF(AND($J18>=DATE(2026,5,1),$J18<EDATE(DATE(2026,5,1),1),TODAY()>=$J18),$G18,0),MAX(0,MIN(IF(TODAY()>$K18,$K18,TODAY()),EDATE(DATE(2026,5,1),1))-MAX($J18,DATE(2026,5,1)))*$G18/($K18-$J18))) -> 0 | Q18: =IF(OR($J18="",$K18="",$G18=""),0,IF($K18<=$J18,IF(AND($J18>=DATE(2026,6,1),$J18<EDATE(DATE(2026,5,1),1),TODAY()>=$J18),$G18,0),MAX(0,MIN(IF(TODAY()>$K18,$K18,TODAY()),EDATE(DATE(2026,6,1),1))-MAX($J18,DATE(2026,6,1)))*$G18/($K18-$J18))) -> 0 | R18: =SUMIF(Tableau!$A:$A,$A18,Tableau!E:E) -> #N/A | S18: =SUMIF(Tableau!$A:$A,$A18,Tableau!F:F) -> #N/A | T18: =SUMIF(Tableau!$A:$A,$A18,Tableau!G:G) -> #N/A | U18: =SUMIF(Tableau!$A:$A,$A18,Tableau!H:H) -> #N/A | V18: =SUMIF(Tableau!$A:$A,$A18,Tableau!I:I) -> #N/A | W18: =SUMIF(Tableau!$A:$A,$A18,Tableau!J:J) -> #N/A | X18: =SUMIF(Tableau!$A:$A,$A18,Tableau!P:P) -> #N/A | Y18: =SUMIF(Tableau!$A:$A,$A18,Tableau!Q:Q) -> #N/A | Z18: =SUMIF(Tableau!$A:$A,$A18,Tableau!R:R) -> #N/A | AA18: =SUMIF(Tableau!$A:$A,$A18,Tableau!S:S) -> #N/A | AB18: =SUMIF(Tableau!$A:$A,$A18,Tableau!T:T) -> #N/A | AC18: =SUMIF(Tableau!$A:$A,$A18,Tableau!U:U) -> #N/A | AL18: =SUM(AF18:AK18) -> 0 | AV18: =SUM(AP18:AU18) -> 8684.7826 | BF18: =SUM(AZ18:BE18) -> #N/A | BH18: Bbasher | BI18: 0 | BJ18: 0 | BK18: 0 | BL18: 0 | BM18: 335.96838 | BN18: 186.3354 | BO18: 222.82609 | CF18: =IFERROR(BT18/BZ18,0) -> 0 | CG18: =IFERROR(BU18/CA18,0) -> 0 | CH18: =IFERROR(BV18/CB18,0) -> 0 | CI18: =IFERROR(BW18/CC18,0) -> 0 | CJ18: =IFERROR(BX18/CD18,0) -> 0 | CK18: =IFERROR(BY18/CE18,0) -> 0
A19: =Data2026!A25 -> bboladin26 | B19: =Data2026!B25 -> 46094 | C19: =Data2026!C25 -> Fixed | D19: =Data2026!D25 -> bboladin26 | E19: =Data2026!E25 -> Nini_B | F19: =Data2026!F25 -> 46094 | G19: =Data2026!G25 | H19: =Data2026!H25 -> Finished | ... K19: =Data2026!K25 -> 46124 | L19: =IF(OR($J19="",$K19="",$G19=""),0,IF($K19<=$J19,IF(AND($J19>=DATE(2026,1,1),$J19<EDATE(DATE(2026,1,1),1),TODAY()>=$J19),$G19,0),MAX(0,MIN(IF(TODAY()>$K19,$K19,TODAY()),EDATE(DATE(2026,1,1),1))-MAX($J19,DATE(2026,1,1)))*$G19/($K19-$J19))) -> 0 | M19: =IF(OR($J19="",$K19="",$G19=""),0,IF($K19<=$J19,IF(AND($J19>=DATE(2026,2,1),$J19<EDATE(DATE(2026,2,1),1),TODAY()>=$J19),$G19,0),MAX(0,MIN(IF(TODAY()>$K19,$K19,TODAY()),EDATE(DATE(2026,2,1),1))-MAX($J19,DATE(2026,2,1)))*$G19/($K19-$J19))) -> 0 | N19: =IF(OR($J19="",$K19="",$G19=""),0,IF($K19<=$J19,IF(AND($J19>=DATE(2026,3,1),$J19<EDATE(DATE(2026,3,1),1),TODAY()>=$J19),$G19,0),MAX(0,MIN(IF(TODAY()>$K19,$K19,TODAY()),EDATE(DATE(2026,3,1),1))-MAX($J19,DATE(2026,3,1)))*$G19/($K19-$J19))) -> 0 | O19: =IF(OR($J19="",$K19="",$G19=""),0,IF($K19<=$J19,IF(AND($J19>=DATE(2026,4,1),$J19<EDATE(DATE(2026,4,1),1),TODAY()>=$J19),$G19,0),MAX(0,MIN(IF(TODAY()>$K19,$K19,TODAY()),EDATE(DATE(2026,4,1),1))-MAX($J19,DATE(2026,4,1)))*$G19/($K19-$J19))) -> 0 | P19: =IF(OR($J19="",$K19="",$G19=""),0,IF($K19<=$J19,IF(AND($J19>=DATE(2026,5,1),$J19<EDATE(DATE(2026,5,1),1),TODAY()>=$J19),$G19,0),MAX(0,MIN(IF(TODAY()>$K19,$K19,TODAY()),EDATE(DATE(2026,5,1),1))-MAX($J19,DATE(2026,5,1)))*$G19/($K19-$J19))) -> 0 | Q19: =IF(OR($J19="",$K19="",$G19=""),0,IF($K19<=$J19,IF(AND($J19>=DATE(2026,6,1),$J19<EDATE(DATE(2026,5,1),1),TODAY()>=$J19),$G19,0),MAX(0,MIN(IF(TODAY()>$K19,$K19,TODAY()),EDATE(DATE(2026,6,1),1))-MAX($J19,DATE(2026,6,1)))*$G19/($K19-$J19))) -> 0 | R19: =SUMIF(Tableau!$A:$A,$A19,Tableau!E:E) -> #N/A | S19: =SUMIF(Tableau!$A:$A,$A19,Tableau!F:F) -> #N/A | T19: =SUMIF(Tableau!$A:$A,$A19,Tableau!G:G) -> #N/A | U19: =SUMIF(Tableau!$A:$A,$A19,Tableau!H:H) -> #N/A | V19: =SUMIF(Tableau!$A:$A,$A19,Tableau!I:I) -> #N/A | W19: =SUMIF(Tableau!$A:$A,$A19,Tableau!J:J) -> #N/A | X19: =SUMIF(Tableau!$A:$A,$A19,Tableau!P:P) -> #N/A | Y19: =SUMIF(Tableau!$A:$A,$A19,Tableau!Q:Q) -> #N/A | Z19: =SUMIF(Tableau!$A:$A,$A19,Tableau!R:R) -> #N/A | AA19: =SUMIF(Tableau!$A:$A,$A19,Tableau!S:S) -> #N/A | AB19: =SUMIF(Tableau!$A:$A,$A19,Tableau!T:T) -> #N/A | AC19: =SUMIF(Tableau!$A:$A,$A19,Tableau!U:U) -> #N/A | AL19: Total | AV19: =SUM(AP19:AU19) -> 0 | BF19: =SUM(AZ19:BE19) -> #N/A | BH19: Xaloslots | BI19: 0 | BJ19: 0 | BK19: 0 | BL19: 0 | BM19: 0 | BN19: 125 | BO19: 125 | CF19: =IFERROR(BT19/BZ19,0) -> 0 | CG19: =IFERROR(BU19/CA19,0) -> 0 | CH19: =IFERROR(BV19/CB19,0) -> 0 | CI19: =IFERROR(BW19/CC19,0) -> 0 | CJ19: =IFERROR(BX19/CD19,0) -> 0 | CK19: =IFERROR(BY19/CE19,0) -> 0
